Workbook

Sheet Inputs
A1: Wong Family model — INPUTS
A2: Blue = hardcoded input. Edit only blue cells. Source in column D.
A4: ECONOMIC
A5: CPI inflation | B5: 0.025 | D5: Pete lock table; HK 2006-25 avg 2.52%
A6: Wage growth — Adrian | B6: 0.03 | D6: Pete lock table
A7: Wage growth — Carmen | B7: 0.03 | D7: Pete lock table
A8: Education escalation (overseas) | B8: 0.05 | D8: Pete lock table
A9: RETURNS (nominal)
A10: Equities | B10: 0.06 | D10: Fahtai 27 Sep: conservative vs Pete's 7.0%
A11: Equity volatility | B11: 0.17 | D11: Pete lock table 16-18%
A12: Bonds / IG | B12: 0.04 | D12: Pete lock table
A13: Treasury ladder | B13: 0.04 | D13: held to maturity, vol ~2%
A14: MPF | B14: 0.05 | D14: Pete lock table
A15: Cash — time deposits | B15: 0.028 | D15: Pete: 3.0% 2027-28 -> 2.5% by 2031
A16: Cash — idle balances | B16: 0.002 | D16: Pete lock table
A17: TAX 2026/27
A18: Basic allowance | B18: 145000 | D18: IR (Amendment) Ordinance 2026
A19: Married allowance | B19: 290000 | D19: IR (Amendment) Ordinance 2026
A20: Child allowance | B20: 140000 | D20: IR (Amendment) Ordinance 2026
A21: Dependent parent 60+ (each) | B21: 55000 | D21: 2 parents assumed, claimed by Adrian
A22: MPF deduction cap | B22: 18000 | D22: per person
A23: Top marginal rate | B23: 0.17 | D23: progressive 2/6/10/14 then 17
A24: Tax on first 200,000 | B24: 16000 | D24: 2%+6%+10%+14% on 50k bands
A25: Mortgage rate (for HLI deduction) | B25: 0.035 | D25: Pete lock table
A26: FAMILY
A27: Adrian's salary | B27: 1050000 | D27: case
A28: Adrian's bonus (planning = low end) | B28: 150000 | D28: case 150-300k; conservative
A29: Carmen's salary / dividend | B29: 720000 | D29: case; treated as all salary
A30: Ryan's salary (EXCLUDED from base case) | B30: 300000 | D30: case; Goal 3 treats him separately
A31: Household expenses (annual) | B31: 984000 | D31: case 82,000/month
A32: Retirement spending (today money) | B32: 780000 | D32: case
A33: Retirement income floor % | B33: 0.4 | D33: Pete, C&SD HES 2024/25 top quartile
A34: MODEL LEVERS
A35: Portfolio return — plan (nominal) | B35: 0.048 | D35: mix 2: 40% eq @6% + 60% ladder @4%
A36: Portfolio return — status quo (nominal) | B36: 0.042 | D36: unmanaged, cash-heavy. TEAM TO AGREE
A37: Emergency reserve target (months) | B37: 12 | D37: vs 30.5 today
A38: Annuity purchase cost at 2037 | B38: 4120000 | D38: Pete: MPF 2.31M (A) + 1.81M (C)
A39: Annuity income (HKMC, annual) | B39: 268000 | D39: Pete: HKMC payout at 65
A40: Education — overseas annual (today) | B40: 600000 | D40: case high end, conservative
A41: Education — years | B41: 4 | D41: 4-year degree
...

Sheet BalanceSheet
A1: Balance sheet — case validation
A3: LIQUID
A4: Savings and current accounts | B4: 620000
A5: Time deposits | B5: 1480000
A6: Money market / short bond fund | B6: 400000
A7: Total liquid | B7: =SUM(B4:B6) -> 2500000
A8: INVESTMENT
A9: HK equity funds | B9: 1000000
A10: Global equity funds | B10: 1350000
A11: Investment-grade bond funds | B11: 900000
A12: ESG / sustainable equity funds | B12: 700000
A13: Green / sustainable bond products | B13: 450000
A14: Listed stocks and REITs | B14: 800000
A15: Adrian's MPF | B15: 1050000
A16: Carmen's MPF | B16: 620000
A17: Ryan's MPF | B17: 180000
A18: Digital assets (all Ryan) | B18: 500000
A19: Cash value of life policies | B19: 420000
A20: Total investment | B20: =SUM(B9:B19) -> 7970000
A21: FIXED
A22: Residential property | B22: 11500000
A23: Carmen's business | B23: 5000000
A24: Motor vehicle | B24: 220000
A25: Total fixed | B25: =SUM(B22:B24) -> 16720000
A26: LIABILITIES
A27: Mortgage | B27: 1800000
A28: Business term loan | B28: 900000
A29: Credit card / revolving | B29: 85000
A30: Total liabilities | B30: =SUM(B27:B29) -> 2785000
A32: TOTAL ASSETS | B32: =B7+B20+B25 -> 27190000
A33: NET WORTH | B33: =B32-B30 -> 24405000
A35: CHECK vs case (should be 0) | B35: =B33-24405000 -> 0
A37: Parents' investable pool (ex Ryan's MPF and digital) | B37: =B7+B20-B17-B18 -> 9790000

Sheet Tax
A1: Salaries tax 2026/27 — separate vs joint assessment
A2: Confirms Pete: separate beats joint by exactly HK$18,000
A4: HLI total (mortgage x rate) | B4: =BalanceSheet!B27*Inputs!$B$25 -> 63000
B6: Adrian | C6: Carmen | D6: Joint | E6: Ryan
A7: Income | B7: =Inputs!$B$27+Inputs!$B$28 -> 1200000 | C7: =Inputs!$B$29 -> 720000 | D7: =B7+C7 -> 1920000 | E7: =Inputs!$B$30 -> 300000
A8: less MPF | B8: =-Inputs!$B$22 -> -18000 | C8: =-Inputs!$B$22 -> -18000 | D8: =B8+C8 -> -36000 | E8: =-MIN(Inputs!$B$22,E7*0.05) -> -15000
A9: less home loan int | B9: =-$B$4/2 -> -31500 | C9: =-$B$4/2 -> -31500 | D9: =B9+C9 -> -63000 | E9: 0
A10: Net income | B10: =SUM(B7:B9) -> 1150500 | C10: =SUM(C7:C9) -> 670500 | D10: =SUM(D7:D9) -> 1821000 | E10: =SUM(E7:E9) -> 285000
A11: less allowances | B11: =-(Inputs!$B$18+Inputs!$B$20+2*Inputs!$B$21) -> -395000 | C11: =-Inputs!$B$18 -> -145000 | D11: =-(Inputs!$B$19+Inputs!$B$20+2*Inputs!$B$21) -> -540000 | E11: =-Inputs!$B$18 -> -145000
A12: Net chargeable income | B12: =MAX(B10+B11,0) -> 755500 | C12: =MAX(C10+C11,0) -> 525500 | D12: =MAX(D10+D11,0) -> 1281000 | E12: =MAX(E10+E11,0) -> 140000
A13: TAX (progressive) | B13: =IF(B12>200000,Inputs!$B$24+(B12-200000)*Inputs!$B$23,IF(B12>150000,9000+(B12-150000)*0.14,IF(B12>100000,4000+(B12-100000)*0.1,IF(B12>50000,1000+(B12-50000)*0.06,B12*0.02)))) -> 110435 | C13: =IF(C12>200000,Inputs!$B$24+(C12-200000)*Inputs!$B$23,IF(C12>150000,9000+(C12-150000)*0.14,IF(C12>100000,4000+(C12-100000)*0.1,IF(C12>50000,1000+(C12-50000)*0.06,C12*0.02)))) -> 71335 | D13: =IF(D12>200000,Inputs!$B$24+(D12-200000)*Inputs!$B$23,IF(D12>150000,9000+(D12-150000)*0.14,IF(D12>100000,4000+(D12-100000)*0.1,IF(D12>50000,1000+(D12-50000)*0.06,D12*0.02)))) -> 199770 | E13: =IF(E12>200000,Inputs!$B$24+(E12-200000)*Inputs!$B$23,IF(E12>150000,9000+(E12-150000)*0.14,IF(E12>100000,4000+(E12-100000)*0.1,IF(E12>50000,1000+(E12-50000)*0.06,E12*0.02)))) -> 8000
A15: COUPLE — separate | B15: =B13+C13 -> 181770
A16: COUPLE — joint | B16: =D13 -> 199770
A17: Separate saves | B17: =B16-B15 -> 18000
A19: CHECK separate = 181,770 | B19: =B15-181770 -> 0
A20: CHECK joint = 199,770 | B20: =B16-199770 -> 0
A22: ANNUAL SURPLUS (parents, after tax and MPF)
A23: Gross income | B23: =D7 -> 1920000
A24: less tax | B24: =-B15 -> -181770
A25: less MPF | B25: =D8 -> -36000
A26: less expenses | B26: =-Inputs!$B$31 -> -984000
A27: SURPLUS | B27: =SUM(B23:B26) -> 718230

Sheet Projection
A1: Year-by-year projection 2026-2072 — every cell driven by the Inputs tab
A2: Black = formula. Change nothing here; change Inputs.
A3: Year | B3: Age A | C3: Age C | D3: Income A | E3: Income C | F3: Allow A | G3: Allow C | H3: Tax A | I3: Tax C | J3: MPF | K3: Living exp | L3: Education | M3: Retire spend | N3: Annuity inc | O3: Net cash flow | P3: Portfolio open | Q3: Investment return | R3: Annuity purchase | S3: Portfolio close
A4: 2026 | B4: =$A4-1972 -> 54 | C4: =$A4-1977 -> 49 | D4: =IF($A4<Inputs!$B$45,(Inputs!$B$27+Inputs!$B$28)*(1+Inputs!$B$6)^($A4-Inputs!$B$44),0) -> 1200000 | E4: =IF($A4<Inputs!$B$46,Inputs!$B$29*(1+Inputs!$B$7)^($A4-Inputs!$B$44),0) -> 720000 | F4: =(Inputs!$B$18+Inputs!$B$20+2*Inputs!$B$21)*(1+Inputs!$B$5)^($A4-Inputs!$B$44) -> 395000 | G4: =Inputs!$B$18*(1+Inputs!$B$5)^($A4-Inputs!$B$44) -> 145000 | H4: =IF(D4=0,0,IF(MAX(D4-Inputs!$B$22-Tax!$B$4/2-F4,0)>200000,Inputs!$B$24+(MAX(D4-Inputs!$B$22-Tax!$B$4/2-F4,0)-200000)*Inputs!$B$23,IF(MAX(D4-Inputs!$B$22-Tax!$B$4/2-F4,0)>150000,9000+(MAX(D4-Inputs!$B$22-Tax!$B$4/2-F4,0)-150000)*0.14,IF(MAX(D4-Inputs!$B$22-Tax!$B$4/2-F4,0)>100000,4000+(MAX(D4-Inputs!$B$22-Tax!$B$4/2-F4,0)-100000)*0.1,IF(MAX(D4-Inputs!$B$22-Tax!$B$4/2-F4,0)>50000,1000+(MAX(D4-Inputs!$B$22-Tax!$B$4/2-F4,0)-50000)*0.06,MAX(MAX(D4-Inputs!$B$22-Tax!$B$4/2-F4,0),0)*0.02))))) -> 110435 | I4: =IF(E4=0,0,IF(MAX(E4-Inputs!$B$22-Tax!$B$4/2-G4,0)>200000,Inputs!$B$24+(MAX(E4-Inputs!$B$22-Tax!$B$4/2-G4,0)-200000)*Inputs!$B$23,IF(MAX(E4-Inputs!$B$22-Tax!$B$4/2-G4,0)>150000,9000+(MAX(E4-Inputs!$B$22-Tax!$B$4/2-G4,0)-150000)*0.14,IF(MAX(E4-Inputs!$B$22-Tax!$B$4/2-G4,0)>100000,4000+(MAX(E4-Inputs!$B$22-Tax!$B$4/2-G4,0)-100000)*0.1,IF(MAX(E4-Inputs!$B$22-Tax!$B$4/2-G4,0)>50000,1000+(MAX(E4-Inputs!$B$22-Tax!$B$4/2-G4,0)-50000)*0.06,MAX(MAX(E4-Inputs!$B$22-Tax!$B$4/2-G4,0),0)*0.02))))) -> 71335 | J4: =IF(D4>0,Inputs!$B$22,0)+IF(E4>0,Inputs!$B$22,0) -> 36000 | K4: =IF($A4<Inputs!$B$45,Inputs!$B$31*(1+Inputs!$B$5)^($A4-Inputs!$B$44),0) -> 984000 | L4: =IF(AND($A4>=Inputs!$B$47,$A4<Inputs!$B$47+Inputs!$B$41),Inputs!$B$40*(1+Inputs!$B$8)^($A4-Inputs!$B$44),0) -> 0 | M4: =IF($A4>=Inputs!$B$45,Inputs!$B$32*(1+Inputs!$B$5)^($A4-Inputs!$B$44),0) -> 0 | N4: =IF($A4>=Inputs!$B$45,Inputs!$B$39,0) -> 0 | O4: =D4+E4-H4-I4-J4-K4-L4-M4+N4-Inputs!$B$42 -> 718230 | P4: =BalanceSheet!$B$37 -> 9790000 | Q4: =P4*Inputs!$B$35 -> 469920 | R4: =IF($A4=Inputs!$B$45,-Inputs!$B$38,0) -> 0 | S4: =MAX(P4+Q4+O4+R4,0) -> 10978150
A5: 2027 | B5: =$A5-1972 -> 55 | C5: =$A5-1977 -> 50 | D5: =IF($A5<Inputs!$B$45,(Inputs!$B$27+Inputs!$B$28)*(1+Inputs!$B$6)^($A5-Inputs!$B$44),0) -> 1236000 | E5: =IF($A5<Inputs!$B$46,Inputs!$B$29*(1+Inputs!$B$7)^($A5-Inputs!$B$44),0) -> 741600 | F5: =(Inputs!$B$18+Inputs!$B$20+2*Inputs!$B$21)*(1+Inputs!$B$5)^($A5-Inputs!$B$44) -> 404875 | G5: =Inputs!$B$18*(1+Inputs!$B$5)^($A5-Inputs!$B$44) -> 148625 | H5: =IF(D5=0,0,IF(MAX(D5-Inputs!$B$22-Tax!$B$4/2-F5,0)>200000,Inputs!$B$24+(MAX(D5-Inputs!$B$22-Tax!$B$4/2-F5,0)-200000)*Inputs!$B$23,IF(MAX(D5-Inputs!$B$22-Tax!$B$4/2-F5,0)>150000,9000+(MAX(D5-Inputs!$B$22-Tax!$B$4/2-F5,0)-150000)*0.14,IF(MAX(D5-Inputs!$B$22-Tax!$B$4/2-F5,0)>100000,4000+(MAX(D5-Inputs!$B$22-Tax!$B$4/2-F5,0)-100000)*0.1,IF(MAX(D5-Inputs!$B$22-Tax!$B$4/2-F5,0)>50000,1000+(MAX(D5-Inputs!$B$22-Tax!$B$4/2-F5,0)-50000)*0.06,MAX(MAX(D5-Inputs!$B$22-Tax!$B$4/2-F5,0),0)*0.02))))) -> 114876.25 | I5: =IF(E5=0,0,IF(MAX(E5-Inputs!$B$22-Tax!$B$4/2-G5,0)>200000,Inputs!$B$24+(MAX(E5-Inputs!$B$22-Tax!$B$4/2-G5,0)-200000)*Inputs!$B$23,IF(MAX(E5-Inputs!$B$22-Tax!$B$4/2-G5,0)>150000,9000+(MAX(E5-Inputs!$B$22-Tax!$B$4/2-G5,0)-150000)*0.14,IF(MAX(E5-Inputs!$B$22-Tax!$B$4/2-G5,0)>100000,4000+(MAX(E5-Inputs!$B$22-Tax!$B$4/2-G5,0)-100000)*0.1,IF(MAX(E5-Inputs!$B$22-Tax!$B$4/2-G5,0)>50000,1000+(MAX(E5-Inputs!$B$22-Tax!$B$4/2-G5,0)-50000)*0.06,MAX(MAX(E5-Inputs!$B$22-Tax!$B$4/2-G5,0),0)*0.02))))) -> 74390.75 | J5: =IF(D5>0,Inputs!$B$22,0)+IF(E5>0,Inputs!$B$22,0) -> 36000 | K5: =IF($A5<Inputs!$B$45,Inputs!$B$31*(1+Inputs!$B$5)^($A5-Inputs!$B$44),0) -> 1008600 | L5: =IF(AND($A5>=Inputs!$B$47,$A5<Inputs!$B$47+Inputs!$B$41),Inputs!$B$40*(1+Inputs!$B$8)^($A5-Inputs!$B$44),0) -> 0 | M5: =IF($A5>=Inputs!$B$45,Inputs!$B$32*(1+Inputs!$B$5)^($A5-Inputs!$B$44),0) -> 0 | N5: =IF($A5>=Inputs!$B$45,Inputs!$B$39,0) -> 0 | O5: =D5+E5-H5-I5-J5-K5-L5-M5+N5-Inputs!$B$42 -> 743733 | P5: =S4 -> 10978150 | Q5: =P5*Inputs!$B$35 -> 526951.2 | R5: =IF($A5=Inputs!$B$45,-Inputs!$B$38,0) -> 0 | S5: =MAX(P5+Q5+O5+R5,0) -> 12248834
A6: 2028 | B6: =$A6-1972 -> 56 | C6: =$A6-1977 -> 51 | D6: =IF($A6<Inputs!$B$45,(Inputs!$B$27+Inputs!$B$28)*(1+Inputs!$B$6)^($A6-Inputs!$B$44),0) -> 1273080 | E6: =IF($A6<Inputs!$B$46,Inputs!$B$29*(1+Inputs!$B$7)^($A6-Inputs!$B$44),0) -> 763848 | F6: =(Inputs!$B$18+Inputs!$B$20+2*Inputs!$B$21)*(1+Inputs!$B$5)^($A6-Inputs!$B$44) -> 414996.88 | G6: =Inputs!$B$18*(1+Inputs!$B$5)^($A6-Inputs!$B$44) -> 152340.62 | H6: =IF(D6=0,0,IF(MAX(D6-Inputs!$B$22-Tax!$B$4/2-F6,0)>200000,Inputs!$B$24+(MAX(D6-Inputs!$B$22-Tax!$B$4/2-F6,0)-200000)*Inputs!$B$23,IF(MAX(D6-Inputs!$B$22-Tax!$B$4/2-F6,0)>150000,9000+(MAX(D6-Inputs!$B$22-Tax!$B$4/2-F6,0)-150000)*0.14,IF(MAX(D6-Inputs!$B$22-Tax!$B$4/2-F6,0)>100000,4000+(MAX(D6-Inputs!$B$22-Tax!$B$4/2-F6,0)-100000)*0.1,IF(MAX(D6-Inputs!$B$22-Tax!$B$4/2-F6,0)>50000,1000+(MAX(D6-Inputs!$B$22-Tax!$B$4/2-F6,0)-50000)*0.06,MAX(MAX(D6-Inputs!$B$22-Tax!$B$4/2-F6,0),0)*0.02))))) -> 119459.13 | I6: =IF(E6=0,0,IF(MAX(E6-Inputs!$B$22-Tax!$B$4/2-G6,0)>200000,Inputs!$B$24+(MAX(E6-Inputs!$B$22-Tax!$B$4/2-G6,0)-200000)*Inputs!$B$23,IF(MAX(E6-Inputs!$B$22-Tax!$B$4/2-G6,0)>150000,9000+(MAX(E6-Inputs!$B$22-Tax!$B$4/2-G6,0)-150000)*0.14,IF(MAX(E6-Inputs!$B$22-Tax!$B$4/2-G6,0)>100000,4000+(MAX(E6-Inputs!$B$22-Tax!$B$4/2-G6,0)-100000)*0.1,IF(MAX(E6-Inputs!$B$22-Tax!$B$4/2-G6,0)>50000,1000+(MAX(E6-Inputs!$B$22-Tax!$B$4/2-G6,0)-50000)*0.06,MAX(MAX(E6-Inputs!$B$22-Tax!$B$4/2-G6,0),0)*0.02))))) -> 77541.254 | J6: =IF(D6>0,Inputs!$B$22,0)+IF(E6>0,Inputs!$B$22,0) -> 36000 | K6: =IF($A6<Inputs!$B$45,Inputs!$B$31*(1+Inputs!$B$5)^($A6-Inputs!$B$44),0) -> 1033815 | L6: =IF(AND($A6>=Inputs!$B$47,$A6<Inputs!$B$47+Inputs!$B$41),Inputs!$B$40*(1+Inputs!$B$8)^($A6-Inputs!$B$44),0) -> 661500 | M6: =IF($A6>=Inputs!$B$45,Inputs!$B$32*(1+Inputs!$B$5)^($A6-Inputs!$B$44),0) -> 0 | N6: =IF($A6>=Inputs!$B$45,Inputs!$B$39,0) -> 0 | O6: =D6+E6-H6-I6-J6-K6-L6-M6+N6-Inputs!$B$42 -> 108612.62 | P6: =S5 -> 12248834 | Q6: =P6*Inputs!$B$35 -> 587944.04 | R6: =IF($A6=Inputs!$B$45,-Inputs!$B$38,0) -> 0 | S6: =MAX(P6+Q6+O6+R6,0) -> 12945391
A7: 2029 | B7: =$A7-1972 -> 57 | C7: =$A7-1977 -> 52 | D7: =IF($A7<Inputs!$B$45,(Inputs!$B$27+Inputs!$B$28)*(1+Inputs!$B$6)^($A7-Inputs!$B$44),0) -> 1311272.4 | E7: =IF($A7<Inputs!$B$46,Inputs!$B$29*(1+Inputs!$B$7)^($A7-Inputs!$B$44),0) -> 786763.44 | F7: =(Inputs!$B$18+Inputs!$B$20+2*Inputs!$B$21)*(1+Inputs!$B$5)^($A7-Inputs!$B$44) -> 425371.8 | G7: =Inputs!$B$18*(1+Inputs!$B$5)^($A7-Inputs!$B$44) -> 156149.14 | H7: =IF(D7=0,0,IF(MAX(D7-Inputs!$B$22-Tax!$B$4/2-F7,0)>200000,Inputs!$B$24+(MAX(D7-Inputs!$B$22-Tax!$B$4/2-F7,0)-200000)*Inputs!$B$23,IF(MAX(D7-Inputs!$B$22-Tax!$B$4/2-F7,0)>150000,9000+(MAX(D7-Inputs!$B$22-Tax!$B$4/2-F7,0)-150000)*0.14,IF(MAX(D7-Inputs!$B$22-Tax!$B$4/2-F7,0)>100000,4000+(MAX(D7-Inputs!$B$22-Tax!$B$4/2-F7,0)-100000)*0.1,IF(MAX(D7-Inputs!$B$22-Tax!$B$4/2-F7,0)>50000,1000+(MAX(D7-Inputs!$B$22-Tax!$B$4/2-F7,0)-50000)*0.06,MAX(MAX(D7-Inputs!$B$22-Tax!$B$4/2-F7,0),0)*0.02))))) -> 124188.1 | I7: =IF(E7=0,0,IF(MAX(E7-Inputs!$B$22-Tax!$B$4/2-G7,0)>200000,Inputs!$B$24+(MAX(E7-Inputs!$B$22-Tax!$B$4/2-G7,0)-200000)*Inputs!$B$23,IF(MAX(E7-Inputs!$B$22-Tax!$B$4/2-G7,0)>150000,9000+(MAX(E7-Inputs!$B$22-Tax!$B$4/2-G7,0)-150000)*0.14,IF(MAX(E7-Inputs!$B$22-Tax!$B$4/2-G7,0)>100000,4000+(MAX(E7-Inputs!$B$22-Tax!$B$4/2-G7,0)-100000)*0.1,IF(MAX(E7-Inputs!$B$22-Tax!$B$4/2-G7,0)>50000,1000+(MAX(E7-Inputs!$B$22-Tax!$B$4/2-G7,0)-50000)*0.06,MAX(MAX(E7-Inputs!$B$22-Tax!$B$4/2-G7,0),0)*0.02))))) -> 80789.431 | J7: =IF(D7>0,Inputs!$B$22,0)+IF(E7>0,Inputs!$B$22,0) -> 36000 | K7: =IF($A7<Inputs!$B$45,Inputs!$B$31*(1+Inputs!$B$5)^($A7-Inputs!$B$44),0) -> 1059660.4 | L7: =IF(AND($A7>=Inputs!$B$47,$A7<Inputs!$B$47+Inputs!$B$41),Inputs!$B$40*(1+Inputs!$B$8)^($A7-Inputs!$B$44),0) -> 694575 | M7: =IF($A7>=Inputs!$B$45,Inputs!$B$32*(1+Inputs!$B$5)^($A7-Inputs!$B$44),0) -> 0 | N7: =IF($A7>=Inputs!$B$45,Inputs!$B$39,0) -> 0 | O7: =D7+E7-H7-I7-J7-K7-L7-M7+N7-Inputs!$B$42 -> 102822.93 | P7: =S6 -> 12945391 | Q7: =P7*Inputs!$B$35 -> 621378.76 | R7: =IF($A7=Inputs!$B$45,-Inputs!$B$38,0) -> 0 | S7: =MAX(P7+Q7+O7+R7,0) -> 13669593
A8: 2030 | B8: =$A8-1972 -> 58 | C8: =$A8-1977 -> 53 | D8: =IF($A8<Inputs!$B$45,(Inputs!$B$27+Inputs!$B$28)*(1+Inputs!$B$6)^($A8-Inputs!$B$44),0) -> 1350610.6 | E8: =IF($A8<Inputs!$B$46,Inputs!$B$29*(1+Inputs!$B$7)^($A8-Inputs!$B$44),0) -> 810366.34 | F8: =(Inputs!$B$18+Inputs!$B$20+2*Inputs!$B$21)*(1+Inputs!$B$5)^($A8-Inputs!$B$44) -> 436006.09 | G8: =Inputs!$B$18*(1+Inputs!$B$5)^($A8-Inputs!$B$44) -> 160052.87 | H8: =IF(D8=0,0,IF(MAX(D8-Inputs!$B$22-Tax!$B$4/2-F8,0)>200000,Inputs!$B$24+(MAX(D8-Inputs!$B$22-Tax!$B$4/2-F8,0)-200000)*Inputs!$B$23,IF(MAX(D8-Inputs!$B$22-Tax!$B$4/2-F8,0)>150000,9000+(MAX(D8-Inputs!$B$22-Tax!$B$4/2-F8,0)-150000)*0.14,IF(MAX(D8-Inputs!$B$22-Tax!$B$4/2-F8,0)>100000,4000+(MAX(D8-Inputs!$B$22-Tax!$B$4/2-F8,0)-100000)*0.1,IF(MAX(D8-Inputs!$B$22-Tax!$B$4/2-F8,0)>50000,1000+(MAX(D8-Inputs!$B$22-Tax!$B$4/2-F8,0)-50000)*0.06,MAX(MAX(D8-Inputs!$B$22-Tax!$B$4/2-F8,0),0)*0.02))))) -> 129067.76 | I8: =IF(E8=0,0,IF(MAX(E8-Inputs!$B$22-Tax!$B$4/2-G8,0)>200000,Inputs!$B$24+(MAX(E8-Inputs!$B$22-Tax!$B$4/2-G8,0)-200000)*Inputs!$B$23,IF(MAX(E8-Inputs!$B$22-Tax!$B$4/2-G8,0)>150000,9000+(MAX(E8-Inputs!$B$22-Tax!$B$4/2-G8,0)-150000)*0.14,IF(MAX(E8-Inputs!$B$22-Tax!$B$4/2-G8,0)>100000,4000+(MAX(E8-Inputs!$B$22-Tax!$B$4/2-G8,0)-100000)*0.1,IF(MAX(E8-Inputs!$B$22-Tax!$B$4/2-G8,0)>50000,1000+(MAX(E8-Inputs!$B$22-Tax!$B$4/2-G8,0)-50000)*0.06,MAX(MAX(E8-Inputs!$B$22-Tax!$B$4/2-G8,0),0)*0.02))))) -> 84138.291 | J8: =IF(D8>0,Inputs!$B$22,0)+IF(E8>0,Inputs!$B$22,0) -> 36000 | K8: =IF($A8<Inputs!$B$45,Inputs!$B$31*(1+Inputs!$B$5)^($A8-Inputs!$B$44),0) -> 1086151.9 | L8: =IF(AND($A8>=Inputs!$B$47,$A8<Inputs!$B$47+Inputs!$B$41),Inputs!$B$40*(1+Inputs!$B$8)^($A8-Inputs!$B$44),0) -> 729303.75 | M8: =IF($A8>=Inputs!$B$45,Inputs!$B$32*(1+Inputs!$B$5)^($A8-Inputs!$B$44),0) -> 0 | N8: =IF($A8>=Inputs!$B$45,Inputs!$B$39,0) -> 0 | O8: =D8+E8-H8-I8-J8-K8-L8-M8+N8-Inputs!$B$42 -> 96315.229 | P8: =S7 -> 13669593 | Q8: =P8*Inputs!$B$35 -> 656140.44 | R8: =IF($A8=Inputs!$B$45,-Inputs!$B$38,0) -> 0 | S8: =MAX(P8+Q8+O8+R8,0) -> 14422048
A9: 2031 | B9: =$A9-1972 -> 59 | C9: =$A9-1977 -> 54 | D9: =IF($A9<Inputs!$B$45,(Inputs!$B$27+Inputs!$B$28)*(1+Inputs!$B$6)^($A9-Inputs!$B$44),0) -> 1391128.9 | E9: =IF($A9<Inputs!$B$46,Inputs!$B$29*(1+Inputs!$B$7)^($A9-Inputs!$B$44),0) -> 834677.33 | F9: =(Inputs!$B$18+Inputs!$B$20+2*Inputs!$B$21)*(1+Inputs!$B$5)^($A9-Inputs!$B$44) -> 446906.24 | G9: =Inputs!$B$18*(1+Inputs!$B$5)^($A9-Inputs!$B$44) -> 164054.19 | H9: =IF(D9=0,0,IF(MAX(D9-Inputs!$B$22-Tax!$B$4/2-F9,0)>200000,Inputs!$B$24+(MAX(D9-Inputs!$B$22-Tax!$B$4/2-F9,0)-200000)*Inputs!$B$23,IF(MAX(D9-Inputs!$B$22-Tax!$B$4/2-F9,0)>150000,9000+(MAX(D9-Inputs!$B$22-Tax!$B$4/2-F9,0)-150000)*0.14,IF(MAX(D9-Inputs!$B$22-Tax!$B$4/2-F9,0)>100000,4000+(MAX(D9-Inputs!$B$22-Tax!$B$4/2-F9,0)-100000)*0.1,IF(MAX(D9-Inputs!$B$22-Tax!$B$4/2-F9,0)>50000,1000+(MAX(D9-Inputs!$B$22-Tax!$B$4/2-F9,0)-50000)*0.06,MAX(MAX(D9-Inputs!$B$22-Tax!$B$4/2-F9,0),0)*0.02))))) -> 134102.85 | I9: =IF(E9=0,0,IF(MAX(E9-Inputs!$B$22-Tax!$B$4/2-G9,0)>200000,Inputs!$B$24+(MAX(E9-Inputs!$B$22-Tax!$B$4/2-G9,0)-200000)*Inputs!$B$23,IF(MAX(E9-Inputs!$B$22-Tax!$B$4/2-G9,0)>150000,9000+(MAX(E9-Inputs!$B$22-Tax!$B$4/2-G9,0)-150000)*0.14,IF(MAX(E9-Inputs!$B$22-Tax!$B$4/2-G9,0)>100000,4000+(MAX(E9-Inputs!$B$22-Tax!$B$4/2-G9,0)-100000)*0.1,IF(MAX(E9-Inputs!$B$22-Tax!$B$4/2-G9,0)>50000,1000+(MAX(E9-Inputs!$B$22-Tax!$B$4/2-G9,0)-50000)*0.06,MAX(MAX(E9-Inputs!$B$22-Tax!$B$4/2-G9,0),0)*0.02))))) -> 87590.934 | J9: =IF(D9>0,Inputs!$B$22,0)+IF(E9>0,Inputs!$B$22,0) -> 36000 | K9: =IF($A9<Inputs!$B$45,Inputs!$B$31*(1+Inputs!$B$5)^($A9-Inputs!$B$44),0) -> 1113305.7 | L9: =IF(AND($A9>=Inputs!$B$47,$A9<Inputs!$B$47+Inputs!$B$41),Inputs!$B$40*(1+Inputs!$B$8)^($A9-Inputs!$B$44),0) -> 765768.94 | M9: =IF($A9>=Inputs!$B$45,Inputs!$B$32*(1+Inputs!$B$5)^($A9-Inputs!$B$44),0) -> 0 | N9: =IF($A9>=Inputs!$B$45,Inputs!$B$39,0) -> 0 | O9: =D9+E9-H9-I9-J9-K9-L9-M9+N9-Inputs!$B$42 -> 89037.82 | P9: =S8 -> 14422048 | Q9: =P9*Inputs!$B$35 -> 692258.31 | R9: =IF($A9=Inputs!$B$45,-Inputs!$B$38,0) -> 0 | S9: =MAX(P9+Q9+O9+R9,0) -> 15203344
A10: 2032 | B10: =$A10-1972 -> 60 | C10: =$A10-1977 -> 55 | D10: =IF($A10<Inputs!$B$45,(Inputs!$B$27+Inputs!$B$28)*(1+Inputs!$B$6)^($A10-Inputs!$B$44),0) -> 1432862.8 | E10: =IF($A10<Inputs!$B$46,Inputs!$B$29*(1+Inputs!$B$7)^($A10-Inputs!$B$44),0) -> 859717.65 | F10: =(Inputs!$B$18+Inputs!$B$20+2*Inputs!$B$21)*(1+Inputs!$B$5)^($A10-Inputs!$B$44) -> 458078.9 | G10: =Inputs!$B$18*(1+Inputs!$B$5)^($A10-Inputs!$B$44) -> 168155.55 | H10: =IF(D10=0,0,IF(MAX(D10-Inputs!$B$22-Tax!$B$4/2-F10,0)>200000,Inputs!$B$24+(MAX(D10-Inputs!$B$22-Tax!$B$4/2-F10,0)-200000)*Inputs!$B$23,IF(MAX(D10-Inputs!$B$22-Tax!$B$4/2-F10,0)>150000,9000+(MAX(D10-Inputs!$B$22-Tax!$B$4/2-F10,0)-150000)*0.14,IF(MAX(D10-Inputs!$B$22-Tax!$B$4/2-F10,0)>100000,4000+(MAX(D10-Inputs!$B$22-Tax!$B$4/2-F10,0)-100000)*0.1,IF(MAX(D10-Inputs!$B$22-Tax!$B$4/2-F10,0)>50000,1000+(MAX(D10-Inputs!$B$22-Tax!$B$4/2-F10,0)-50000)*0.06,MAX(MAX(D10-Inputs!$B$22-Tax!$B$4/2-F10,0),0)*0.02))))) -> 139298.26 | I10: =IF(E10=0,0,IF(MAX(E10-Inputs!$B$22-Tax!$B$4/2-G10,0)>200000,Inputs!$B$24+(MAX(E10-Inputs!$B$22-Tax!$B$4/2-G10,0)-200000)*Inputs!$B$23,IF(MAX(E10-Inputs!$B$22-Tax!$B$4/2-G10,0)>150000,9000+(MAX(E10-Inputs!$B$22-Tax!$B$4/2-G10,0)-150000)*0.14,IF(MAX(E10-Inputs!$B$22-Tax!$B$4/2-G10,0)>100000,4000+(MAX(E10-Inputs!$B$22-Tax!$B$4/2-G10,0)-100000)*0.1,IF(MAX(E10-Inputs!$B$22-Tax!$B$4/2-G10,0)>50000,1000+(MAX(E10-Inputs!$B$22-Tax!$B$4/2-G10,0)-50000)*0.06,MAX(MAX(E10-Inputs!$B$22-Tax!$B$4/2-G10,0),0)*0.02))))) -> 91150.558 | J10: =IF(D10>0,Inputs!$B$22,0)+IF(E10>0,Inputs!$B$22,0) -> 36000 | K10: =IF($A10<Inputs!$B$45,Inputs!$B$31*(1+Inputs!$B$5)^($A10-Inputs!$B$44),0) -> 1141138.3 | L10: =IF(AND($A10>=Inputs!$B$47,$A10<Inputs!$B$47+Inputs!$B$41),Inputs!$B$40*(1+Inputs!$B$8)^($A10-Inputs!$B$44),0) -> 0 | M10: =IF($A10>=Inputs!$B$45,Inputs!$B$32*(1+Inputs!$B$5)^($A10-Inputs!$B$44),0) -> 0 | N10: =IF($A10>=Inputs!$B$45,Inputs!$B$39,0) -> 0 | O10: =D10+E10-H10-I10-J10-K10-L10-M10+N10-Inputs!$B$42 -> 884993.27 | P10: =S9 -> 15203344 | Q10: =P10*Inputs!$B$35 -> 729760.53 | R10: =IF($A10=Inputs!$B$45,-Inputs!$B$38,0) -> 0 | S10: =MAX(P10+Q10+O10+R10,0) -> 16818098
A11: 2033 | B11: =$A11-1972 -> 61 | C11: =$A11-1977 -> 56 | D11: =IF($A11<Inputs!$B$45,(Inputs!$B$27+Inputs!$B$28)*(1+Inputs!$B$6)^($A11-Inputs!$B$44),0) -> 1475848.6 | E11: =IF($A11<Inputs!$B$46,Inputs!$B$29*(1+Inputs!$B$7)^($A11-Inputs!$B$44),0) -> 885509.18 | F11: =(Inputs!$B$18+Inputs!$B$20+2*Inputs!$B$21)*(1+Inputs!$B$5)^($A11-Inputs!$B$44) -> 469530.87 | G11: =Inputs!$B$18*(1+Inputs!$B$5)^($A11-Inputs!$B$44) -> 172359.43 | H11: =IF(D11=0,0,IF(MAX(D11-Inputs!$B$22-Tax!$B$4/2-F11,0)>200000,Inputs!$B$24+(MAX(D11-Inputs!$B$22-Tax!$B$4/2-F11,0)-200000)*Inputs!$B$23,IF(MAX(D11-Inputs!$B$22-Tax!$B$4/2-F11,0)>150000,9000+(MAX(D11-Inputs!$B$22-Tax!$B$4/2-F11,0)-150000)*0.14,IF(MAX(D11-Inputs!$B$22-Tax!$B$4/2-F11,0)>100000,4000+(MAX(D11-Inputs!$B$22-Tax!$B$4/2-F11,0)-100000)*0.1,IF(MAX(D11-Inputs!$B$22-Tax!$B$4/2-F11,0)>50000,1000+(MAX(D11-Inputs!$B$22-Tax!$B$4/2-F11,0)-50000)*0.06,MAX(MAX(D11-Inputs!$B$22-Tax!$B$4/2-F11,0),0)*0.02))))) -> 144659.02 | I11: =IF(E11=0,0,IF(MAX(E11-Inputs!$B$22-Tax!$B$4/2-G11,0)>200000,Inputs!$B$24+(MAX(E11-Inputs!$B$22-Tax!$B$4/2-G11,0)-200000)*Inputs!$B$23,IF(MAX(E11-Inputs!$B$22-Tax!$B$4/2-G11,0)>150000,9000+(MAX(E11-Inputs!$B$22-Tax!$B$4/2-G11,0)-150000)*0.14,IF(MAX(E11-Inputs!$B$22-Tax!$B$4/2-G11,0)>100000,4000+(MAX(E11-Inputs!$B$22-Tax!$B$4/2-G11,0)-100000)*0.1,IF(MAX(E11-Inputs!$B$22-Tax!$B$4/2-G11,0)>50000,1000+(MAX(E11-Inputs!$B$22-Tax!$B$4/2-G11,0)-50000)*0.06,MAX(MAX(E11-Inputs!$B$22-Tax!$B$4/2-G11,0),0)*0.02))))) -> 94820.457 | J11: =IF(D11>0,Inputs!$B$22,0)+IF(E11>0,Inputs!$B$22,0) -> 36000 | K11: =IF($A11<Inputs!$B$45,Inputs!$B$31*(1+Inputs!$B$5)^($A11-Inputs!$B$44),0) -> 1169666.8 | L11: =IF(AND($A11>=Inputs!$B$47,$A11<Inputs!$B$47+Inputs!$B$41),Inputs!$B$40*(1+Inputs!$B$8)^($A11-Inputs!$B$44),0) -> 0 | M11: =IF($A11>=Inputs!$B$45,Inputs!$B$32*(1+Inputs!$B$5)^($A11-Inputs!$B$44),0) -> 0 | N11: =IF($A11>=Inputs!$B$45,Inputs!$B$39,0) -> 0 | O11: =D11+E11-H11-I11-J11-K11-L11-M11+N11-Inputs!$B$42 -> 916211.56 | P11: =S10 -> 16818098 | Q11: =P11*Inputs!$B$35 -> 807268.71 | R11: =IF($A11=Inputs!$B$45,-Inputs!$B$38,0) -> 0 | S11: =MAX(P11+Q11+O11+R11,0) -> 18541578
A12: 2034 | B12: =$A12-1972 -> 62 | C12: =$A12-1977 -> 57 | D12: =IF($A12<Inputs!$B$45,(Inputs!$B$27+Inputs!$B$28)*(1+Inputs!$B$6)^($A12-Inputs!$B$44),0) -> 1520124.1 | E12: =IF($A12<Inputs!$B$46,Inputs!$B$29*(1+Inputs!$B$7)^($A12-Inputs!$B$44),0) -> 912074.46 | F12: =(Inputs!$B$18+Inputs!$B$20+2*Inputs!$B$21)*(1+Inputs!$B$5)^($A12-Inputs!$B$44) -> 481269.14 | G12: =Inputs!$B$18*(1+Inputs!$B$5)^($A12-Inputs!$B$44) -> 176668.42 | H12: =IF(D12=0,0,IF(MAX(D12-Inputs!$B$22-Tax!$B$4/2-F12,0)>200000,Inputs!$B$24+(MAX(D12-Inputs!$B$22-Tax!$B$4/2-F12,0)-200000)*Inputs!$B$23,IF(MAX(D12-Inputs!$B$22-Tax!$B$4/2-F12,0)>150000,9000+(MAX(D12-Inputs!$B$22-Tax!$B$4/2-F12,0)-150000)*0.14,IF(MAX(D12-Inputs!$B$22-Tax!$B$4/2-F12,0)>100000,4000+(MAX(D12-Inputs!$B$22-Tax!$B$4/2-F12,0)-100000)*0.1,IF(MAX(D12-Inputs!$B$22-Tax!$B$4/2-F12,0)>50000,1000+(MAX(D12-Inputs!$B$22-Tax!$B$4/2-F12,0)-50000)*0.06,MAX(MAX(D12-Inputs!$B$22-Tax!$B$4/2-F12,0),0)*0.02))))) -> 150190.34 | I12: =IF(E12=0,0,IF(MAX(E12-Inputs!$B$22-Tax!$B$4/2-G12,0)>200000,Inputs!$B$24+(MAX(E12-Inputs!$B$22-Tax!$B$4/2-G12,0)-200000)*Inputs!$B$23,IF(MAX(E12-Inputs!$B$22-Tax!$B$4/2-G12,0)>150000,9000+(MAX(E12-Inputs!$B$22-Tax!$B$4/2-G12,0)-150000)*0.14,IF(MAX(E12-Inputs!$B$22-Tax!$B$4/2-G12,0)>100000,4000+(MAX(E12-Inputs!$B$22-Tax!$B$4/2-G12,0)-100000)*0.1,IF(MAX(E12-Inputs!$B$22-Tax!$B$4/2-G12,0)>50000,1000+(MAX(E12-Inputs!$B$22-Tax!$B$4/2-G12,0)-50000)*0.06,MAX(MAX(E12-Inputs!$B$22-Tax!$B$4/2-G12,0),0)*0.02))))) -> 98604.027 | J12: =IF(D12>0,Inputs!$B$22,0)+IF(E12>0,Inputs!$B$22,0) -> 36000 | K12: =IF($A12<Inputs!$B$45,Inputs!$B$31*(1+Inputs!$B$5)^($A12-Inputs!$B$44),0) -> 1198908.5 | L12: =IF(AND($A12>=Inputs!$B$47,$A12<Inputs!$B$47+Inputs!$B$41),Inputs!$B$40*(1+Inputs!$B$8)^($A12-Inputs!$B$44),0) -> 0 | M12: =IF($A12>=Inputs!$B$45,Inputs!$B$32*(1+Inputs!$B$5)^($A12-Inputs!$B$44),0) -> 0 | N12: =IF($A12>=Inputs!$B$45,Inputs!$B$39,0) -> 0 | O12: =D12+E12-H12-I12-J12-K12-L12-M12+N12-Inputs!$B$42 -> 948495.74 | P12: =S11 -> 18541578 | Q12: =P12*Inputs!$B$35 -> 889995.76 | R12: =IF($A12=Inputs!$B$45,-Inputs!$B$38,0) -> 0 | S12: =MAX(P12+Q12+O12+R12,0) -> 20380070
A13: 2035 | B13: =$A13-1972 -> 63 | C13: =$A13-1977 -> 58 | D13: =IF($A13<Inputs!$B$45,(Inputs!$B$27+Inputs!$B$28)*(1+Inputs!$B$6)^($A13-Inputs!$B$44),0) -> 1565727.8 | E13: =IF($A13<Inputs!$B$46,Inputs!$B$29*(1+Inputs!$B$7)^($A13-Inputs!$B$44),0) -> 939436.69 | F13: =(Inputs!$B$18+Inputs!$B$20+2*Inputs!$B$21)*(1+Inputs!$B$5)^($A13-Inputs!$B$44) -> 493300.87 | G13: =Inputs!$B$18*(1+Inputs!$B$5)^($A13-Inputs!$B$44) -> 181085.13 | H13: =IF(D13=0,0,IF(MAX(D13-Inputs!$B$22-Tax!$B$4/2-F13,0)>200000,Inputs!$B$24+(MAX(D13-Inputs!$B$22-Tax!$B$4/2-F13,0)-200000)*Inputs!$B$23,IF(MAX(D13-Inputs!$B$22-Tax!$B$4/2-F13,0)>150000,9000+(MAX(D13-Inputs!$B$22-Tax!$B$4/2-F13,0)-150000)*0.14,IF(MAX(D13-Inputs!$B$22-Tax!$B$4/2-F13,0)>100000,4000+(MAX(D13-Inputs!$B$22-Tax!$B$4/2-F13,0)-100000)*0.1,IF(MAX(D13-Inputs!$B$22-Tax!$B$4/2-F13,0)>50000,1000+(MAX(D13-Inputs!$B$22-Tax!$B$4/2-F13,0)-50000)*0.06,MAX(MAX(D13-Inputs!$B$22-Tax!$B$4/2-F13,0),0)*0.02))))) -> 155897.58 | I13: =IF(E13=0,0,IF(MAX(E13-Inputs!$B$22-Tax!$B$4/2-G13,0)>200000,Inputs!$B$24+(MAX(E13-Inputs!$B$22-Tax!$B$4/2-G13,0)-200000)*Inputs!$B$23,IF(MAX(E13-Inputs!$B$22-Tax!$B$4/2-G13,0)>150000,9000+(MAX(E13-Inputs!$B$22-Tax!$B$4/2-G13,0)-150000)*0.14,IF(MAX(E13-Inputs!$B$22-Tax!$B$4/2-G13,0)>100000,4000+(MAX(E13-Inputs!$B$22-Tax!$B$4/2-G13,0)-100000)*0.1,IF(MAX(E13-Inputs!$B$22-Tax!$B$4/2-G13,0)>50000,1000+(MAX(E13-Inputs!$B$22-Tax!$B$4/2-G13,0)-50000)*0.06,MAX(MAX(E13-Inputs!$B$22-Tax!$B$4/2-G13,0),0)*0.02))))) -> 102504.77 | J13: =IF(D13>0,Inputs!$B$22,0)+IF(E13>0,Inputs!$B$22,0) -> 36000 | K13: =IF($A13<Inputs!$B$45,Inputs!$B$31*(1+Inputs!$B$5)^($A13-Inputs!$B$44),0) -> 1228881.2 | L13: =IF(AND($A13>=Inputs!$B$47,$A13<Inputs!$B$47+Inputs!$B$41),Inputs!$B$40*(1+Inputs!$B$8)^($A13-Inputs!$B$44),0) -> 0 | M13: =IF($A13>=Inputs!$B$45,Inputs!$B$32*(1+Inputs!$B$5)^($A13-Inputs!$B$44),0) -> 0 | N13: =IF($A13>=Inputs!$B$45,Inputs!$B$39,0) -> 0 | O13: =D13+E13-H13-I13-J13-K13-L13-M13+N13-Inputs!$B$42 -> 981881 | P13: =S12 -> 20380070 | Q13: =P13*Inputs!$B$35 -> 978243.36 | R13: =IF($A13=Inputs!$B$45,-Inputs!$B$38,0) -> 0 | S13: =MAX(P13+Q13+O13+R13,0) -> 22340194
A14: 2036 | B14: =$A14-1972 -> 64 | C14: =$A14-1977 -> 59 | D14: =IF($A14<Inputs!$B$45,(Inputs!$B$27+Inputs!$B$28)*(1+Inputs!$B$6)^($A14-Inputs!$B$44),0) -> 1612699.7 | E14: =IF($A14<Inputs!$B$46,Inputs!$B$29*(1+Inputs!$B$7)^($A14-Inputs!$B$44),0) -> 967619.79 | F14: =(Inputs!$B$18+Inputs!$B$20+2*Inputs!$B$21)*(1+Inputs!$B$5)^($A14-Inputs!$B$44) -> 505633.39 | G14: =Inputs!$B$18*(1+Inputs!$B$5)^($A14-Inputs!$B$44) -> 185612.26 | H14: =IF(D14=0,0,IF(MAX(D14-Inputs!$B$22-Tax!$B$4/2-F14,0)>200000,Inputs!$B$24+(MAX(D14-Inputs!$B$22-Tax!$B$4/2-F14,0)-200000)*Inputs!$B$23,IF(MAX(D14-Inputs!$B$22-Tax!$B$4/2-F14,0)>150000,9000+(MAX(D14-Inputs!$B$22-Tax!$B$4/2-F14,0)-150000)*0.14,IF(MAX(D14-Inputs!$B$22-Tax!$B$4/2-F14,0)>100000,4000+(MAX(D14-Inputs!$B$22-Tax!$B$4/2-F14,0)-100000)*0.1,IF(MAX(D14-Inputs!$B$22-Tax!$B$4/2-F14,0)>50000,1000+(MAX(D14-Inputs!$B$22-Tax!$B$4/2-F14,0)-50000)*0.06,MAX(MAX(D14-Inputs!$B$22-Tax!$B$4/2-F14,0),0)*0.02))))) -> 161786.26 | I14: =IF(E14=0,0,IF(MAX(E14-Inputs!$B$22-Tax!$B$4/2-G14,0)>200000,Inputs!$B$24+(MAX(E14-Inputs!$B$22-Tax!$B$4/2-G14,0)-200000)*Inputs!$B$23,IF(MAX(E14-Inputs!$B$22-Tax!$B$4/2-G14,0)>150000,9000+(MAX(E14-Inputs!$B$22-Tax!$B$4/2-G14,0)-150000)*0.14,IF(MAX(E14-Inputs!$B$22-Tax!$B$4/2-G14,0)>100000,4000+(MAX(E14-Inputs!$B$22-Tax!$B$4/2-G14,0)-100000)*0.1,IF(MAX(E14-Inputs!$B$22-Tax!$B$4/2-G14,0)>50000,1000+(MAX(E14-Inputs!$B$22-Tax!$B$4/2-G14,0)-50000)*0.06,MAX(MAX(E14-Inputs!$B$22-Tax!$B$4/2-G14,0),0)*0.02))))) -> 106526.28 | J14: =IF(D14>0,Inputs!$B$22,0)+IF(E14>0,Inputs!$B$22,0) -> 36000 | K14: =IF($A14<Inputs!$B$45,Inputs!$B$31*(1+Inputs!$B$5)^($A14-Inputs!$B$44),0) -> 1259603.2 | L14: =IF(AND($A14>=Inputs!$B$47,$A14<Inputs!$B$47+Inputs!$B$41),Inputs!$B$40*(1+Inputs!$B$8)^($A14-Inputs!$B$44),0) -> 0 | M14: =IF($A14>=Inputs!$B$45,Inputs!$B$32*(1+Inputs!$B$5)^($A14-Inputs!$B$44),0) -> 0 | N14: =IF($A14>=Inputs!$B$45,Inputs!$B$39,0) -> 0 | O14: =D14+E14-H14-I14-J14-K14-L14-M14+N14-Inputs!$B$42 -> 1016403.7 | P14: =S13 -> 22340194 | Q14: =P14*Inputs!$B$35 -> 1072329.3 | R14: =IF($A14=Inputs!$B$45,-Inputs!$B$38,0) -> 0 | S14: =MAX(P14+Q14+O14+R14,0) -> 24428927
A15: 2037 | B15: =$A15-1972 -> 65 | C15: =$A15-1977 -> 60 | D15: =IF($A15<Inputs!$B$45,(Inputs!$B$27+Inputs!$B$28)*(1+Inputs!$B$6)^($A15-Inputs!$B$44),0) -> 0 | E15: =IF($A15<Inputs!$B$46,Inputs!$B$29*(1+Inputs!$B$7)^($A15-Inputs!$B$44),0) -> 996648.39 | F15: =(Inputs!$B$18+Inputs!$B$20+2*Inputs!$B$21)*(1+Inputs!$B$5)^($A15-Inputs!$B$44) -> 518274.23 | G15: =Inputs!$B$18*(1+Inputs!$B$5)^($A15-Inputs!$B$44) -> 190252.57 | H15: =IF(D15=0,0,IF(MAX(D15-Inputs!$B$22-Tax!$B$4/2-F15,0)>200000,Inputs!$B$24+(MAX(D15-Inputs!$B$22-Tax!$B$4/2-F15,0)-200000)*Inputs!$B$23,IF(MAX(D15-Inputs!$B$22-Tax!$B$4/2-F15,0)>150000,9000+(MAX(D15-Inputs!$B$22-Tax!$B$4/2-F15,0)-150000)*0.14,IF(MAX(D15-Inputs!$B$22-Tax!$B$4/2-F15,0)>100000,4000+(MAX(D15-Inputs!$B$22-Tax!$B$4/2-F15,0)-100000)*0.1,IF(MAX(D15-Inputs!$B$22-Tax!$B$4/2-F15,0)>50000,1000+(MAX(D15-Inputs!$B$22-Tax!$B$4/2-F15,0)-50000)*0.06,MAX(MAX(D15-Inputs!$B$22-Tax!$B$4/2-F15,0),0)*0.02))))) -> 0 | I15: =IF(E15=0,0,IF(MAX(E15-Inputs!$B$22-Tax!$B$4/2-G15,0)>200000,Inputs!$B$24+(MAX(E15-Inputs!$B$22-Tax!$B$4/2-G15,0)-200000)*Inputs!$B$23,IF(MAX(E15-Inputs!$B$22-Tax!$B$4/2-G15,0)>150000,9000+(MAX(E15-Inputs!$B$22-Tax!$B$4/2-G15,0)-150000)*0.14,IF(MAX(E15-Inputs!$B$22-Tax!$B$4/2-G15,0)>100000,4000+(MAX(E15-Inputs!$B$22-Tax!$B$4/2-G15,0)-100000)*0.1,IF(MAX(E15-Inputs!$B$22-Tax!$B$4/2-G15,0)>50000,1000+(MAX(E15-Inputs!$B$22-Tax!$B$4/2-G15,0)-50000)*0.06,MAX(MAX(E15-Inputs!$B$22-Tax!$B$4/2-G15,0),0)*0.02))))) -> 110672.29 | J15: =IF(D15>0,Inputs!$B$22,0)+IF(E15>0,Inputs!$B$22,0) -> 18000 | K15: =IF($A15<Inputs!$B$45,Inputs!$B$31*(1+Inputs!$B$5)^($A15-Inputs!$B$44),0) -> 0 | L15: =IF(AND($A15>=Inputs!$B$47,$A15<Inputs!$B$47+Inputs!$B$41),Inputs!$B$40*(1+Inputs!$B$8)^($A15-Inputs!$B$44),0) -> 0 | M15: =IF($A15>=Inputs!$B$45,Inputs!$B$32*(1+Inputs!$B$5)^($A15-Inputs!$B$44),0) -> 1023427.6 | N15: =IF($A15>=Inputs!$B$45,Inputs!$B$39,0) -> 268000 | O15: =D15+E15-H15-I15-J15-K15-L15-M15+N15-Inputs!$B$42 -> 112548.5 | P15: =S14 -> 24428927 | Q15: =P15*Inputs!$B$35 -> 1172588.5 | R15: =IF($A15=Inputs!$B$45,-Inputs!$B$38,0) -> -4120000 | S15: =MAX(P15+Q15+O15+R15,0) -> 21594064
A16: 2038 | B16: =$A16-1972 -> 66 | C16: =$A16-1977 -> 61 | D16: =IF($A16<Inputs!$B$45,(Inputs!$B$27+Inputs!$B$28)*(1+Inputs!$B$6)^($A16-Inputs!$B$44),0) -> 0 | E16: =IF($A16<Inputs!$B$46,Inputs!$B$29*(1+Inputs!$B$7)^($A16-Inputs!$B$44),0) -> 1026547.8 | F16: =(Inputs!$B$18+Inputs!$B$20+2*Inputs!$B$21)*(1+Inputs!$B$5)^($A16-Inputs!$B$44) -> 531231.09 | G16: =Inputs!$B$18*(1+Inputs!$B$5)^($A16-Inputs!$B$44) -> 195008.88 | H16: =IF(D16=0,0,IF(MAX(D16-Inputs!$B$22-Tax!$B$4/2-F16,0)>200000,Inputs!$B$24+(MAX(D16-Inputs!$B$22-Tax!$B$4/2-F16,0)-200000)*Inputs!$B$23,IF(MAX(D16-Inputs!$B$22-Tax!$B$4/2-F16,0)>150000,9000+(MAX(D16-Inputs!$B$22-Tax!$B$4/2-F16,0)-150000)*0.14,IF(MAX(D16-Inputs!$B$22-Tax!$B$4/2-F16,0)>100000,4000+(MAX(D16-Inputs!$B$22-Tax!$B$4/2-F16,0)-100000)*0.1,IF(MAX(D16-Inputs!$B$22-Tax!$B$4/2-F16,0)>50000,1000+(MAX(D16-Inputs!$B$22-Tax!$B$4/2-F16,0)-50000)*0.06,MAX(MAX(D16-Inputs!$B$22-Tax!$B$4/2-F16,0),0)*0.02))))) -> 0 | I16: =IF(E16=0,0,IF(MAX(E16-Inputs!$B$22-Tax!$B$4/2-G16,0)>200000,Inputs!$B$24+(MAX(E16-Inputs!$B$22-Tax!$B$4/2-G16,0)-200000)*Inputs!$B$23,IF(MAX(E16-Inputs!$B$22-Tax!$B$4/2-G16,0)>150000,9000+(MAX(E16-Inputs!$B$22-Tax!$B$4/2-G16,0)-150000)*0.14,IF(MAX(E16-Inputs!$B$22-Tax!$B$4/2-G16,0)>100000,4000+(MAX(E16-Inputs!$B$22-Tax!$B$4/2-G16,0)-100000)*0.1,IF(MAX(E16-Inputs!$B$22-Tax!$B$4/2-G16,0)>50000,1000+(MAX(E16-Inputs!$B$22-Tax!$B$4/2-G16,0)-50000)*0.06,MAX(MAX(E16-Inputs!$B$22-Tax!$B$4/2-G16,0),0)*0.02))))) -> 114946.62 | J16: =IF(D16>0,Inputs!$B$22,0)+IF(E16>0,Inputs!$B$22,0) -> 18000 | K16: =IF($A16<Inputs!$B$45,Inputs!$B$31*(1+Inputs!$B$5)^($A16-Inputs!$B$44),0) -> 0 | L16: =IF(AND($A16>=Inputs!$B$47,$A16<Inputs!$B$47+Inputs!$B$41),Inputs!$B$40*(1+Inputs!$B$8)^($A16-Inputs!$B$44),0) -> 0 | M16: =IF($A16>=Inputs!$B$45,Inputs!$B$32*(1+Inputs!$B$5)^($A16-Inputs!$B$44),0) -> 1049013.3 | N16: =IF($A16>=Inputs!$B$45,Inputs!$B$39,0) -> 268000 | O16: =D16+E16-H16-I16-J16-K16-L16-M16+N16-Inputs!$B$42 -> 112587.93 | P16: =S15 -> 21594064 | Q16: =P16*Inputs!$B$35 -> 1036515.1 | R16: =IF($A16=Inputs!$B$45,-Inputs!$B$38,0) -> 0 | S16: =MAX(P16+Q16+O16+R16,0) -> 22743167
... A50: 2072 | B50: =$A50-1972 -> 100 | C50: =$A50-1977 -> 95 | D50: =IF($A50<Inputs!$B$45,(Inputs!$B$27+Inputs!$B$28)*(1+Inputs!$B$6)^($A50-Inputs!$B$44),0) -> 0 | E50: =IF($A50<Inputs!$B$46,Inputs!$B$29*(1+Inputs!$B$7)^($A50-Inputs!$B$44),0) -> 0 | F50: =(Inputs!$B$18+Inputs!$B$20+2*Inputs!$B$21)*(1+Inputs!$B$5)^($A50-Inputs!$B$44) -> 1229971.1 | G50: =Inputs!$B$18*(1+Inputs!$B$5)^($A50-Inputs!$B$44) -> 451508.37 | H50: =IF(D50=0,0,IF(MAX(D50-Inputs!$B$22-Tax!$B$4/2-F50,0)>200000,Inputs!$B$24+(MAX(D50-Inputs!$B$22-Tax!$B$4/2-F50,0)-200000)*Inputs!$B$23,IF(MAX(D50-Inputs!$B$22-Tax!$B$4/2-F50,0)>150000,9000+(MAX(D50-Inputs!$B$22-Tax!$B$4/2-F50,0)-150000)*0.14,IF(MAX(D50-Inputs!$B$22-Tax!$B$4/2-F50,0)>100000,4000+(MAX(D50-Inputs!$B$22-Tax!$B$4/2-F50,0)-100000)*0.1,IF(MAX(D50-Inputs!$B$22-Tax!$B$4/2-F50,0)>50000,1000+(MAX(D50-Inputs!$B$22-Tax!$B$4/2-F50,0)-50000)*0.06,MAX(MAX(D50-Inputs!$B$22-Tax!$B$4/2-F50,0),0)*0.02))))) -> 0 | I50: =IF(E50=0,0,IF(MAX(E50-Inputs!$B$22-Tax!$B$4/2-G50,0)>200000,Inputs!$B$24+(MAX(E50-Inputs!$B$22-Tax!$B$4/2-G50,0)-200000)*Inputs!$B$23,IF(MAX(E50-Inputs!$B$22-Tax!$B$4/2-G50,0)>150000,9000+(MAX(E50-Inputs!$B$22-Tax!$B$4/2-G50,0)-150000)*0.14,IF(MAX(E50-Inputs!$B$22-Tax!$B$4/2-G50,0)>100000,4000+(MAX(E50-Inputs!$B$22-Tax!$B$4/2-G50,0)-100000)*0.1,IF(MAX(E50-Inputs!$B$22-Tax!$B$4/2-G50,0)>50000,1000+(MAX(E50-Inputs!$B$22-Tax!$B$4/2-G50,0)-50000)*0.06,MAX(MAX(E50-Inputs!$B$22-Tax!$B$4/2-G50,0),0)*0.02))))) -> 0 | J50: =IF(D50>0,Inputs!$B$22,0)+IF(E50>0,Inputs!$B$22,0) -> 0 | K50: =IF($A50<Inputs!$B$45,Inputs!$B$31*(1+Inputs!$B$5)^($A50-Inputs!$B$44),0) -> 0 | L50: =IF(AND($A50>=Inputs!$B$47,$A50<Inputs!$B$47+Inputs!$B$41),Inputs!$B$40*(1+Inputs!$B$8)^($A50-Inputs!$B$44),0) -> 0 | M50: =IF($A50>=Inputs!$B$45,Inputs!$B$32*(1+Inputs!$B$5)^($A50-Inputs!$B$44),0) -> 2428803.7 | N50: =IF($A50>=Inputs!$B$45,Inputs!$B$39,0) -> 268000 | O50: =D50+E50-H50-I50-J50-K50-L50-M50+N50-Inputs!$B$42 -> -2160803.7 | P50: =S49 -> 13463696 | Q50: =P50*Inputs!$B$35 -> 646257.39 | R50: =IF($A50=Inputs!$B$45,-Inputs!$B$38,0) -> 0 | S50: =MAX(P50+Q50+O50+R50,0) -> 11949149

Sheet Outputs
A1: OUTPUTS — the only numbers that go in the proposal
A2: Green = pulled from another tab. Quote these, not your own arithmetic.
A4: POSITION TODAY
A5: Net worth | B5: =BalanceSheet!B33 -> 24405000
A6: Parents' investable pool | B6: =BalanceSheet!$B$37 -> 9790000
A7: Annual surplus (after tax, MPF, premiums) | B7: =Tax!B27-Inputs!$B$42 -> 718230
A8: Emergency reserve, months | B8: =BalanceSheet!B7/(Inputs!$B$31/12) -> 30.487805
A9: TAX
A10: Couple — separate assessment | B10: =Tax!B15 -> 181770
A11: Couple — joint assessment | B11: =Tax!B16 -> 199770
A12: Saving from separate | B12: =Tax!B17 -> 18000
A13: PROJECTION
A14: Portfolio at Adrian's retirement (2037, nominal) | B14: =INDEX(Projection!S:S,MATCH(Inputs!$B$45,Projection!A:A,0)) -> 21594064
A15: Portfolio at Carmen 89 (2066) | B15: =INDEX(Projection!S:S,MATCH(Inputs!$B$48,Projection!A:A,0)) -> 19285598
A16: Portfolio at Carmen 95 (2072) | B16: =INDEX(Projection!S:S,MATCH(Inputs!$B$49,Projection!A:A,0)) -> 11949149
A17: Portfolio at 2037 in TODAY money | B17: =INDEX(Projection!S:S,MATCH(Inputs!$B$45,Projection!A:A,0))/(1+Inputs!$B$5)^(Inputs!$B$45-Inputs!$B$44) -> 16457803
A18: Retirement need at 2037 (today money) | B18: =780000*(1-(1+0.02)^-29)/0.02 -> 17038620
A19: Funded ratio | B19: =B17/B18 -> 0.96591176
A20: Total education cost (nominal) | B20: =SUM(Projection!L4:L50) -> 2851147.7
A21: Money lasts to 89? (deterministic) | B21: =IF(INDEX(Projection!S:S,MATCH(Inputs!$B$48,Projection!A:A,0))>0,"YES","NO") -> YES
A22: Money lasts to 95? (deterministic) | B22: =IF(INDEX(Projection!S:S,MATCH(Inputs!$B$49,Projection!A:A,0))>0,"YES","NO") -> YES
